<?xml version="1.0" ?>
<robot name="mycobot" xmlns:xacro="http://ros.org/wiki/xacro">
  <link name="g_base">
    <visual>
      <geometry>
        <mesh filename="/home/tejas/Desktop/ros_project/workspace/src/mycobot/urdf/meshes/G_base.dae"/>
      </geometry>
      <origin rpy="0 0 1.5708" xyz="0 0 -0.03"/>
    </visual>
    <collision>
      <geometry>
        <mesh filename="/home/tejas/Desktop/ros_project/workspace/src/mycobot/urdf/meshes/G_base.dae"/>
      </geometry>
      <origin rpy="0 0 1.5708" xyz="0 0 -0.03"/>
    </collision>
  </link>
  
  <link name="joint1">
    <inertial>
      <origin rpy="0 0 0" xyz="0 0 0"/>
      <mass value="0.12"/>
      <inertia ixx="0.000148" ixy="0.0" ixz="0.0" iyy="0.000148" iyz="0.0" izz="0.000096"/>
    </inertial>
    <visual>
      <geometry>
        <mesh filename="/home/tejas/Desktop/ros_project/workspace/src/mycobot/urdf/meshes/joint1.stl"/>
      </geometry>
      <origin rpy="1.5708 0 0" xyz="0 0 0"/>
    </visual>
    <collision>
      <geometry>
          <box size="0.08 0.12 0.075"/>
        </geometry>
      <origin rpy="0 0 0" xyz="0 0 0"/>
    </collision>
  </link>
  
  <link name="joint2">
    <inertial>
      <origin rpy="0 0 0" xyz="0 0 0"/>
      <mass value="0.19"/>
      <inertia ixx="0.000148" ixy="0.0" ixz="0.0" iyy="0.000148" iyz="0.0" izz="0.000096"/>
    </inertial>
    <visual>
      <geometry>
        <mesh filename="/home/tejas/Desktop/ros_project/workspace/src/mycobot/urdf/meshes/joint2.dae"/>
      </geometry>
      <origin rpy="0 0 -1.5708" xyz="0 0 -0.06096"/>
    </visual>
    <collision>
      <geometry>
          <cylinder radius="0.025" length="0.085"/>
      </geometry>
      <origin rpy="0 0 -1.5708" xyz="0 0 -0.06096"/>
    </collision>
  </link>
  
  <link name="joint3">
    <inertial>
      <origin rpy="0 0 0" xyz="0 0 0"/>
      <mass value="0.16"/>
      <inertia ixx="0.000148" ixy="0.0" ixz="0.0" iyy="0.000148" iyz="0.0" izz="0.000096"/>
    </inertial>
    <visual>
      <geometry>
        <mesh filename="/home/tejas/Desktop/ros_project/workspace/src/mycobot/urdf/meshes/joint3.dae"/>
      </geometry>
      <origin rpy="0 -1.5708 0" xyz="0 0 0.03256"/>
    </visual>
    <collision>
      <geometry>
          <cylinder radius="0.025" length="0.15"/>
      </geometry>
      <origin rpy="0 -1.5708 0" xyz="0 0 0.03256"/>
    </collision>
  </link>
  
  <link name="joint4">
    <inertial>
      <origin rpy="0 0 0" xyz="0 0 0"/>
      <mass value="0.124"/>
      <inertia ixx="0.000103" ixy="0.0" ixz="0.0" iyy="0.000103" iyz="0.0" izz="0.000096"/>
    </inertial>
    <visual>
      <geometry>
        <mesh filename="/home/tejas/Desktop/ros_project/workspace/src/mycobot/urdf/meshes/joint4.dae"/>
      </geometry>
      <origin rpy="0 -1.5708 0" xyz="0 0 0.03056"/>
    </visual>
    <collision>
      <geometry>
          <cylinder radius="0.025" length="0.125"/>
      </geometry>
      <origin rpy="0 -1.5708 0" xyz="0 0 0.03056"/>
    </collision>
  </link>
  
  <link name="joint5">
    <inertial>
      <origin rpy="0 0 0" xyz="0 0 0"/>
      <mass value="0.11"/>
      <inertia ixx="0.000103" ixy="0.0" ixz="0.0" iyy="0.000103" iyz="0.0" izz="0.000096"/>
    </inertial>
    <visual>
      <geometry>
        <mesh filename="/home/tejas/Desktop/ros_project/workspace/src/mycobot/urdf/meshes/joint5.stl"/>
      </geometry>
      <origin rpy="0 -1.5708 3.1416" xyz="0 -0.001 -0.0345"/>
    </visual>
    <collision>
      <geometry>
          <box size="0.03 0.035 0.05"/>
      </geometry>
      <origin rpy="0 -1.5708 1.5708" xyz="0 -0.001 -0.0345"/>
    </collision>
  </link>
  
  <link name="joint6">
    <inertial>
      <origin rpy="0 0 0" xyz="0 0 0"/>
      <mass value="0.0739"/>
      <inertia ixx="0.00006649" ixy="0.0" ixz="0.0" iyy="0.00006649" iyz="0.0" izz="0.000096"/>
    </inertial>
    <visual>
      <geometry>
        <mesh filename="/home/tejas/Desktop/ros_project/workspace/src/mycobot/urdf/meshes/joint6.dae"/>
      </geometry>
      <origin rpy="0 0 0" xyz="0 0 -0.038"/>
    </visual>
    <collision>
      <geometry>
          <cylinder radius="0.025" length="0.06"/>
      </geometry>
      <origin rpy="0 0 0" xyz="0 0 -0.038"/>
    </collision>
  </link>
  
  <link name="joint6_flange">
    <inertial>
      <origin rpy="0 0 0" xyz="0 0 0"/>
      <mass value="0.0035"/>
      <inertia ixx="0.0000149" ixy="0.0" ixz="0.0" iyy="0.0000149" iyz="0.0" izz="0.0000196"/>
    </inertial>
    <visual>
      <geometry>
        <mesh filename="/home/tejas/Desktop/ros_project/workspace/src/mycobot/urdf/meshes/joint7.dae"/>
      </geometry>
      <origin rpy="0 0 0" xyz="0 0 -0.012"/>
    </visual>
    <collision>
      <geometry>
          <cylinder radius="0.02" length="0.02"/>
      </geometry>
      <origin rpy="0 0 0" xyz="0 0 -0.012"/>
    </collision>
  </link>
  
  <joint name="g_base_to_joint1" type="fixed">
    <parent link="g_base"/>
    <child link="joint1"/>
    <origin rpy="0 0 0" xyz="0 0 0"/>
  </joint>
  
  <joint name="joint2_to_joint1" type="revolute">
    <axis xyz="0 0 1"/>
    <limit effort="1000.0" lower="-2.9322" upper="2.9322" velocity="3.0"/>
    <parent link="joint1"/>
    <child link="joint2"/>
    <origin rpy="0 0 0" xyz="0 0 0.13956"/>
  </joint>
  
  <joint name="joint3_to_joint2" type="revolute">
    <axis xyz="0 0 1"/>
    <limit effort="1000.0" lower="-2.3562" upper="2.3562" velocity="3.0"/>
    <parent link="joint2"/>
    <child link="joint3"/>
    <origin rpy="0 1.5708 -1.5708" xyz="0 0 -0.001"/>
  </joint>
  
  <joint name="joint4_to_joint3" type="revolute">
    <axis xyz="0 0 1"/>
    <limit effort="1000.0" lower="-2.618" upper="2.618" velocity="3.0"/>
    <parent link="joint3"/>
    <child link="joint4"/>
    <origin rpy="0 0 0" xyz="-0.1104 0 0"/>
  </joint>
  
  <joint name="joint5_to_joint4" type="revolute">
    <axis xyz="0 0 1"/>
    <limit effort="1000.0" lower="-2.5307" upper="2.5307" velocity="3.0"/>
    <parent link="joint4"/>
    <child link="joint5"/>
    <origin rpy="0 0 -1.5708" xyz="-0.096 0 0.06462"/>
  </joint>
  
  <joint name="joint6_to_joint5" type="revolute">
    <axis xyz="0 0 1"/>
    <limit effort="1000.0" lower="-2.8798" upper="2.8798" velocity="3.0"/>
    <parent link="joint5"/>
    <child link="joint6"/>
    <origin rpy="1.5708 -1.5708 0" xyz="0 -0.07318 -0.001"/>
  </joint>
  
  <joint name="joint6output_to_joint6" type="revolute">
    <axis xyz="0 0 1"/>
    <limit effort="1000.0" lower="-3.14159" upper="3.14159" velocity="3.0"/>
    <parent link="joint6"/>
    <child link="joint6_flange"/>
    <origin rpy="-1.5708 0 0" xyz="0 0.0456 0"/>
  </joint>
  
  <gazebo>
    <plugin name="gz_ros2_control::GazeboSimROS2ControlPlugin"
            filename="libgz_ros2_control-system.so">
      <parameters>/home/tejas/Desktop/ros_project/workspace/src/mycobot/config/ros2_controllers.yaml</parameters>
    </plugin>
  </gazebo>

  
  <ros2_control name="GazeboSimSystem" type="system">
    <hardware>
      <plugin>gz_ros2_control/GazeboSimSystem</plugin>
    </hardware>
    <joint name="joint2_to_joint1">
      <command_interface name="position"/>
      <state_interface name="position"/>
      <state_interface name="velocity"/>
    </joint>
    
    <joint name="joint3_to_joint2">
      <command_interface name="position"/>
      <state_interface name="position"/>
      <state_interface name="velocity"/>
    </joint>
    
    <joint name="joint4_to_joint3">
      <command_interface name="position"/>
      <state_interface name="position"/>
      <state_interface name="velocity"/>
    </joint>
    
    <joint name="joint5_to_joint4">
      <command_interface name="position"/>
      <state_interface name="position"/>
      <state_interface name="velocity"/>
    </joint>
    
    <joint name="joint6_to_joint5">
      <command_interface name="position"/>
      <state_interface name="position"/>
      <state_interface name="velocity"/>
    </joint>
    
    <joint name="joint6output_to_joint6">
      <command_interface name="position"/>
      <state_interface name="position"/>
      <state_interface name="velocity"/>
    </joint>
  </ros2_control>
  
  
</robot>

